Traceback (most recent call last):
  File "/Users/dcy/Library/Caches/pypoetry/virtualenvs/prime-cd3412-9bVxcOH5-py3.11/lib/python3.11/site-packages/jupyter_cache/executors/utils.py", line 58, in single_nb_execution
    executenb(
  File "/Users/dcy/Library/Caches/pypoetry/virtualenvs/prime-cd3412-9bVxcOH5-py3.11/lib/python3.11/site-packages/nbclient/client.py", line 1305, in execute
    return NotebookClient(nb=nb, resources=resources, km=km, **kwargs).execute()
           ^^^^^^^^^^^^^^^^^^^^^^^^^^^^^^^^^^^^^^^^^^^^^^^^^^^^^^^^^^^^^^^^^^^^^
  File "/Users/dcy/Library/Caches/pypoetry/virtualenvs/prime-cd3412-9bVxcOH5-py3.11/lib/python3.11/site-packages/jupyter_core/utils/__init__.py", line 173, in wrapped
    return loop.run_until_complete(inner)
           ^^^^^^^^^^^^^^^^^^^^^^^^^^^^^^
  File "/Users/dcy/anaconda3/lib/python3.11/asyncio/base_events.py", line 653, in run_until_complete
    return future.result()
           ^^^^^^^^^^^^^^^
  File "/Users/dcy/Library/Caches/pypoetry/virtualenvs/prime-cd3412-9bVxcOH5-py3.11/lib/python3.11/site-packages/nbclient/client.py", line 705, in async_execute
    await self.async_execute_cell(
  File "/Users/dcy/Library/Caches/pypoetry/virtualenvs/prime-cd3412-9bVxcOH5-py3.11/lib/python3.11/site-packages/nbclient/client.py", line 1058, in async_execute_cell
    await self._check_raise_for_error(cell, cell_index, exec_reply)
  File "/Users/dcy/Library/Caches/pypoetry/virtualenvs/prime-cd3412-9bVxcOH5-py3.11/lib/python3.11/site-packages/nbclient/client.py", line 914, in _check_raise_for_error
    raise CellExecutionError.from_cell_and_msg(cell, exec_reply_content)
nbclient.exceptions.CellExecutionError: An error occurred while executing the following cell:
------------------
import prime_cd3412

print(prime_cd3412.__version__)
------------------


[0;31m---------------------------------------------------------------------------[0m
[0;31mModuleNotFoundError[0m                       Traceback (most recent call last)
Cell [0;32mIn[1], line 1[0m
[0;32m----> 1[0m [38;5;28;01mimport[39;00m [38;5;21;01mprime_cd3412[39;00m
[1;32m      3[0m [38;5;28mprint[39m(prime_cd3412[38;5;241m.[39m__version__)

[0;31mModuleNotFoundError[0m: No module named 'prime_cd3412'

